Workbook

Sheet moras
A1: IDENTIFICACION | B1: SEXO | C1: SALARIO | D1: TIPO_ASEGURAMIENTO | E1: SECTOR | F1: INDICADOR_ACTIVO | G1: INDICADOR.EXTRANJERO | H1: INDICADOR_MOROSO | I1: EDAD | J1: SALARIO_ATÍPICO | K1: EDAD_ATÍPICO
A2: 1252 | B2: MUJER | C2: 251072.18 | D2: PENSIONADOS EN SU PROPIO SISTEMA | E2: SECTOR PUBLICO | F2: SI | G2: NO | H2: NO | I2: 14 | J2: =IF(ABS((C2-AVERAGE($C:$C))/_xlfn.STDEV.S(moras[SALARIO]))>1.96,"Atípico","No") -> No | K2: =IF(ABS((moras[[#This Row],[EDAD]]-AVERAGE($I:$I))/_xlfn.STDEV.S($I:$I))>1.96,"Atípico","No") -> Atípico
A3: 4369 | B3: MUJER | C3: 355899.18 | D3: PENSIONADOS EN SU PROPIO SISTEMA | E3: SECTOR PUBLICO | F3: SI | G3: NO | H3: NO | I3: 17 | J3: =IF(ABS((C3-AVERAGE($C:$C))/_xlfn.STDEV.S(moras[SALARIO]))>1.96,"Atípico","No") -> No | K3: =IF(ABS((moras[[#This Row],[EDAD]]-AVERAGE($I:$I))/_xlfn.STDEV.S($I:$I))>1.96,"Atípico","No") -> No
A4: 2374 | B4: MUJER | C4: 638675 | D4: ASALARIADO | E4: SECTOR PRIVADO | F4: SI | G4: NO | H4: NO | I4: 18 | J4: =IF(ABS((C4-AVERAGE($C:$C))/_xlfn.STDEV.S(moras[SALARIO]))>1.96,"Atípico","No") -> No | K4: =IF(ABS((moras[[#This Row],[EDAD]]-AVERAGE($I:$I))/_xlfn.STDEV.S($I:$I))>1.96,"Atípico","No") -> No
A5: 4336 | B5: MUJER | C5: 423276.21 | D5: ASALARIADO | E5: SECTOR PRIVADO | F5: SI | G5: NO | H5: NO | I5: 18 | J5: =IF(ABS((C5-AVERAGE($C:$C))/_xlfn.STDEV.S(moras[SALARIO]))>1.96,"Atípico","No") -> No | K5: =IF(ABS((moras[[#This Row],[EDAD]]-AVERAGE($I:$I))/_xlfn.STDEV.S($I:$I))>1.96,"Atípico","No") -> No
A6: 2300 | B6: HOMBRE | C6: 347000 | D6: ASALARIADO | E6: SECTOR PRIVADO | F6: SI | G6: NO | H6: NO | I6: 18 | J6: =IF(ABS((C6-AVERAGE($C:$C))/_xlfn.STDEV.S(moras[SALARIO]))>1.96,"Atípico","No") -> No | K6: =IF(ABS((moras[[#This Row],[EDAD]]-AVERAGE($I:$I))/_xlfn.STDEV.S($I:$I))>1.96,"Atípico","No") -> No
A7: 1700 | B7: HOMBRE | C7: 309927.25 | D7: ASALARIADO | E7: SECTOR PRIVADO | F7: SI | G7: NO | H7: NO | I7: 18 | J7: =IF(ABS((C7-AVERAGE($C:$C))/_xlfn.STDEV.S(moras[SALARIO]))>1.96,"Atípico","No") -> No | K7: =IF(ABS((moras[[#This Row],[EDAD]]-AVERAGE($I:$I))/_xlfn.STDEV.S($I:$I))>1.96,"Atípico","No") -> No
A8: 2810 | B8: HOMBRE | C8: 273450.7 | D8: ASALARIADO | E8: SECTOR PRIVADO | F8: SI | G8: NO | H8: NO | I8: 18 | J8: =IF(ABS((C8-AVERAGE($C:$C))/_xlfn.STDEV.S(moras[SALARIO]))>1.96,"Atípico","No") -> No | K8: =IF(ABS((moras[[#This Row],[EDAD]]-AVERAGE($I:$I))/_xlfn.STDEV.S($I:$I))>1.96,"Atípico","No") -> No
A9: 683 | B9: HOMBRE | C9: 240000 | D9: ASALARIADO | E9: SECTOR PRIVADO | F9: SI | G9: NO | H9: NO | I9: 18 | J9: =IF(ABS((C9-AVERAGE($C:$C))/_xlfn.STDEV.S(moras[SALARIO]))>1.96,"Atípico","No") -> No | K9: =IF(ABS((moras[[#This Row],[EDAD]]-AVERAGE($I:$I))/_xlfn.STDEV.S($I:$I))>1.96,"Atípico","No") -> No
A10: 4939 | B10: MUJER | C10: 233740 | D10: ASALARIADO | E10: SECTOR PRIVADO | F10: SI | G10: NO | H10: NO | I10: 18 | J10: =IF(ABS((C10-AVERAGE($C:$C))/_xlfn.STDEV.S(moras[SALARIO]))>1.96,"Atípico","No") -> No | K10: =IF(ABS((moras[[#This Row],[EDAD]]-AVERAGE($I:$I))/_xlfn.STDEV.S($I:$I))>1.96,"Atípico","No") -> No
A11: 24 | B11: HOMBRE | C11: 191744.68 | D11: ASALARIADO | E11: SECTOR PRIVADO | F11: SI | G11: NO | H11: NO | I11: 18 | J11: =IF(ABS((C11-AVERAGE($C:$C))/_xlfn.STDEV.S(moras[SALARIO]))>1.96,"Atípico","No") -> No | K11: =IF(ABS((moras[[#This Row],[EDAD]]-AVERAGE($I:$I))/_xlfn.STDEV.S($I:$I))>1.96,"Atípico","No") -> No
A12: 1294 | B12: HOMBRE | C12: 60000 | D12: ASALARIADO | E12: SECTOR PRIVADO | F12: SI | G12: NO | H12: SI | I12: 18 | J12: =IF(ABS((C12-AVERAGE($C:$C))/_xlfn.STDEV.S(moras[SALARIO]))>1.96,"Atípico","No") -> No | K12: =IF(ABS((moras[[#This Row],[EDAD]]-AVERAGE($I:$I))/_xlfn.STDEV.S($I:$I))>1.96,"Atípico","No") -> No
A13: 2943 | B13: HOMBRE | C13: 25000 | D13: ASALARIADO | E13: SECTOR PRIVADO | F13: SI | G13: NO | H13: NO | I13: 18 | J13: =IF(ABS((C13-AVERAGE($C:$C))/_xlfn.STDEV.S(moras[SALARIO]))>1.96,"Atípico","No") -> No | K13: =IF(ABS((moras[[#This Row],[EDAD]]-AVERAGE($I:$I))/_xlfn.STDEV.S($I:$I))>1.96,"Atípico","No") -> No
... A967: 2043 | B967: MUJER | C967: 26956.8 | D967: ASALARIADO | E967: SECTOR PRIVADO | F967: SI | G967: NO | H967: NO | I967: 28 | J967: =IF(ABS((C967-AVERAGE($C:$C))/_xlfn.STDEV.S(moras[SALARIO]))>1.96,"Atípico","No") -> No | K967: =IF(ABS((moras[[#This Row],[EDAD]]-AVERAGE($I:$I))/_xlfn.STDEV.S($I:$I))>1.96,"Atípico","No") -> No
A968: 21 | B968: MUJER | D968: ASALARIADO | E968: SECTOR PRIVADO | F968: SI | G968: SI | H968: NO | I968: 28 | J968: =IF(ABS((C968-AVERAGE($C:$C))/_xlfn.STDEV.S(moras[SALARIO]))>1.96,"Atípico","No") -> No | K968: =IF(ABS((moras[[#This Row],[EDAD]]-AVERAGE($I:$I))/_xlfn.STDEV.S($I:$I))>1.96,"Atípico","No") -> No
A969: 1482 | B969: MUJER | C969: 2398731.5 | D969: ASALARIADO | E969: SECTOR PUBLICO | F969: SI | G969: NO | H969: NO | I969: 29 | J969: =IF(ABS((C969-AVERAGE($C:$C))/_xlfn.STDEV.S(moras[SALARIO]))>1.96,"Atípico","No") -> Atípico | K969: =IF(ABS((moras[[#This Row],[EDAD]]-AVERAGE($I:$I))/_xlfn.STDEV.S($I:$I))>1.96,"Atípico","No") -> No
A970: 2671 | B970: MUJER | C970: 1794936 | D970: ASALARIADO | E970: SECTOR PRIVADO | F970: SI | G970: NO | H970: NO | I970: 29 | J970: =IF(ABS((C970-AVERAGE($C:$C))/_xlfn.STDEV.S(moras[SALARIO]))>1.96,"Atípico","No") -> No | K970: =IF(ABS((moras[[#This Row],[EDAD]]-AVERAGE($I:$I))/_xlfn.STDEV.S($I:$I))>1.96,"Atípico","No") -> No
A971: 4385 | B971: MUJER | C971: 1482847 | D971: ASALARIADO | E971: SECTOR PUBLICO | F971: SI | G971: NO | H971: SI | I971: 29 | J971: =IF(ABS((C971-AVERAGE($C:$C))/_xlfn.STDEV.S(moras[SALARIO]))>1.96,"Atípico","No") -> No | K971: =IF(ABS((moras[[#This Row],[EDAD]]-AVERAGE($I:$I))/_xlfn.STDEV.S($I:$I))>1.96,"Atípico","No") -> No
A972: 3926 | B972: HOMBRE | C972: 1481119.2 | D972: ASALARIADO | E972: SECTOR PRIVADO | F972: SI | G972: NO | H972: NO | I972: 29 | J972: =IF(ABS((C972-AVERAGE($C:$C))/_xlfn.STDEV.S(moras[SALARIO]))>1.96,"Atípico","No") -> No | K972: =IF(ABS((moras[[#This Row],[EDAD]]-AVERAGE($I:$I))/_xlfn.STDEV.S($I:$I))>1.96,"Atípico","No") -> No
A973: 1995 | B973: HOMBRE | C973: 1352723.7 | D973: ASALARIADO | E973: SECTOR PUBLICO | F973: SI | G973: NO | H973: NO | I973: 29 | J973: =IF(ABS((C973-AVERAGE($C:$C))/_xlfn.STDEV.S(moras[SALARIO]))>1.96,"Atípico","No") -> No | K973: =IF(ABS((moras[[#This Row],[EDAD]]-AVERAGE($I:$I))/_xlfn.STDEV.S($I:$I))>1.96,"Atípico","No") -> No
A974: 2343 | B974: HOMBRE | C974: 1250000 | D974: ASALARIADO | E974: SECTOR PRIVADO | F974: SI | G974: NO | H974: NO | I974: 29 | J974: =IF(ABS((C974-AVERAGE($C:$C))/_xlfn.STDEV.S(moras[SALARIO]))>1.96,"Atípico","No") -> No | K974: =IF(ABS((moras[[#This Row],[EDAD]]-AVERAGE($I:$I))/_xlfn.STDEV.S($I:$I))>1.96,"Atípico","No") -> No
A975: 767 | B975: HOMBRE | C975: 1214906 | D975: ASALARIADO | E975: SECTOR PUBLICO | F975: SI | G975: NO | H975: NO | I975: 29 | J975: =IF(ABS((C975-AVERAGE($C:$C))/_xlfn.STDEV.S(moras[SALARIO]))>1.96,"Atípico","No") -> No | K975: =IF(ABS((moras[[#This Row],[EDAD]]-AVERAGE($I:$I))/_xlfn.STDEV.S($I:$I))>1.96,"Atípico","No") -> No
A976: 4040 | B976: MUJER | C976: 1206489.1 | D976: ASALARIADO | E976: SECTOR PRIVADO | F976: SI | G976: NO | H976: NO | I976: 29 | J976: =IF(ABS((C976-AVERAGE($C:$C))/_xlfn.STDEV.S(moras[SALARIO]))>1.96,"Atípico","No") -> No | K976: =IF(ABS((moras[[#This Row],[EDAD]]-AVERAGE($I:$I))/_xlfn.STDEV.S($I:$I))>1.96,"Atípico","No") -> No
A977: 3203 | B977: HOMBRE | C977: 1160637.1 | D977: ASALARIADO | E977: SECTOR PRIVADO | F977: SI | G977: NO | H977: SI | I977: 29 | J977: =IF(ABS((C977-AVERAGE($C:$C))/_xlfn.STDEV.S(moras[SALARIO]))>1.96,"Atípico","No") -> No | K977: =IF(ABS((moras[[#This Row],[EDAD]]-AVERAGE($I:$I))/_xlfn.STDEV.S($I:$I))>1.96,"Atípico","No") -> No
A978: 4110 | B978: MUJER | C978: 1125420 | D978: ASALARIADO | E978: SECTOR PUBLICO | F978: SI | G978: NO | H978: SI | I978: 29 | J978: =IF(ABS((C978-AVERAGE($C:$C))/_xlfn.STDEV.S(moras[SALARIO]))>1.96,"Atípico","No") -> No | K978: =IF(ABS((moras[[#This Row],[EDAD]]-AVERAGE($I:$I))/_xlfn.STDEV.S($I:$I))>1.96,"Atípico","No") -> No
A979: 3330 | B979: HOMBRE | C979: 1066381.1 | D979: ASALARIADO | E979: SECTOR PRIVADO | F979: SI | G979: NO | H979: NO | I979: 29 | J979: =IF(ABS((C979-AVERAGE($C:$C))/_xlfn.STDEV.S(moras[SALARIO]))>1.96,"Atípico","No") -> No | K979: =IF(ABS((moras[[#This Row],[EDAD]]-AVERAGE($I:$I))/_xlfn.STDEV.S($I:$I))>1.96,"Atípico","No") -> No
A980: 2706 | B980: MUJER | C980: 1061946.5 | D980: ASALARIADO | E980: SECTOR PUBLICO | F980: SI | G980: NO | H980: NO | I980: 29 | J980: =IF(ABS((C980-AVERAGE($C:$C))/_xlfn.STDEV.S(moras[SALARIO]))>1.96,"Atípico","No") -> No | K980: =IF(ABS((moras[[#This Row],[EDAD]]-AVERAGE($I:$I))/_xlfn.STDEV.S($I:$I))>1.96,"Atípico","No") -> No
... A2554: 3727 | B2554: HOMBRE | C2554: 299744 | D2554: TRABAJADOR INDEPENDIENTE | E2554: SECTOR PRIVADO | F2554: SI | G2554: NO | H2554: NO | I2554: 40 | J2554: =IF(ABS((C2554-AVERAGE($C:$C))/_xlfn.STDEV.S(moras[SALARIO]))>1.96,"Atípico","No") -> No | K2554: =IF(ABS((moras[[#This Row],[EDAD]]-AVERAGE($I:$I))/_xlfn.STDEV.S($I:$I))>1.96,"Atípico","No") -> No
A2555: 151 | B2555: MUJER | C2555: 299647 | E2555: SECTOR PRIVADO | F2555: SI | G2555: NO | H2555: NO | I2555: 40 | J2555: =IF(ABS((C2555-AVERAGE($C:$C))/_xlfn.STDEV.S(moras[SALARIO]))>1.96,"Atípico","No") -> No | K2555: =IF(ABS((moras[[#This Row],[EDAD]]-AVERAGE($I:$I))/_xlfn.STDEV.S($I:$I))>1.96,"Atípico","No") -> No
A2556: 973 | B2556: MUJER | C2556: 299647 | D2556: ASEGURADO VOLUNTARIO | E2556: SECTOR PRIVADO | F2556: SI | G2556: NO | H2556: NO | I2556: 40 | J2556: =IF(ABS((C2556-AVERAGE($C:$C))/_xlfn.STDEV.S(moras[SALARIO]))>1.96,"Atípico","No") -> No | K2556: =IF(ABS((moras[[#This Row],[EDAD]]-AVERAGE($I:$I))/_xlfn.STDEV.S($I:$I))>1.96,"Atípico","No") -> No
A2557: 3091 | B2557: HOMBRE | C2557: 299441 | D2557: TRABAJADOR INDEPENDIENTE | E2557: SECTOR PRIVADO | F2557: SI | G2557: SI | H2557: SI | I2557: 40 | J2557: =IF(ABS((C2557-AVERAGE($C:$C))/_xlfn.STDEV.S(moras[SALARIO]))>1.96,"Atípico","No") -> No | K2557: =IF(ABS((moras[[#This Row],[EDAD]]-AVERAGE($I:$I))/_xlfn.STDEV.S($I:$I))>1.96,"Atípico","No") -> No
A2558: 1849 | B2558: MUJER | C2558: 299046 | D2558: TRABAJADOR INDEPENDIENTE | E2558: SECTOR PRIVADO | F2558: SI | G2558: SI | H2558: NO | I2558: 40 | J2558: =IF(ABS((C2558-AVERAGE($C:$C))/_xlfn.STDEV.S(moras[SALARIO]))>1.96,"Atípico","No") -> No | K2558: =IF(ABS((moras[[#This Row],[EDAD]]-AVERAGE($I:$I))/_xlfn.STDEV.S($I:$I))>1.96,"Atípico","No") -> No
A2559: 476 | B2559: HOMBRE | C2559: 298195 | D2559: TRABAJADOR INDEPENDIENTE | E2559: SECTOR PRIVADO | F2559: SI | G2559: NO | H2559: SI | I2559: 40 | J2559: =IF(ABS((C2559-AVERAGE($C:$C))/_xlfn.STDEV.S(moras[SALARIO]))>1.96,"Atípico","No") -> No | K2559: =IF(ABS((moras[[#This Row],[EDAD]]-AVERAGE($I:$I))/_xlfn.STDEV.S($I:$I))>1.96,"Atípico","No") -> No
A2560: 123 | B2560: MUJER | C2560: 297062 | D2560: ASEGURADO VOLUNTARIO | E2560: SECTOR PRIVADO | F2560: SI | G2560: NO | H2560: NO | I2560: 40 | J2560: =IF(ABS((C2560-AVERAGE($C:$C))/_xlfn.STDEV.S(moras[SALARIO]))>1.96,"Atípico","No") -> No | K2560: =IF(ABS((moras[[#This Row],[EDAD]]-AVERAGE($I:$I))/_xlfn.STDEV.S($I:$I))>1.96,"Atípico","No") -> No
A2561: 282 | B2561: MUJER | C2561: 297062 | D2561: TRABAJADOR INDEPENDIENTE | E2561: SECTOR PRIVADO | F2561: SI | G2561: NO | H2561: SI | I2561: 40 | J2561: =IF(ABS((C2561-AVERAGE($C:$C))/_xlfn.STDEV.S(moras[SALARIO]))>1.96,"Atípico","No") -> No | K2561: =IF(ABS((moras[[#This Row],[EDAD]]-AVERAGE($I:$I))/_xlfn.STDEV.S($I:$I))>1.96,"Atípico","No") -> No
A2562: 1289 | B2562: MUJER | C2562: 297046 | D2562: TRABAJADOR INDEPENDIENTE | E2562: SECTOR PRIVADO | F2562: SI | G2562: NO | H2562: NO | I2562: 40 | J2562: =IF(ABS((C2562-AVERAGE($C:$C))/_xlfn.STDEV.S(moras[SALARIO]))>1.96,"Atípico","No") -> No | K2562: =IF(ABS((moras[[#This Row],[EDAD]]-AVERAGE($I:$I))/_xlfn.STDEV.S($I:$I))>1.96,"Atípico","No") -> No
A2563: 1357 | B2563: MUJER | C2563: 297046 | D2563: ASEGURADO VOLUNTARIO | E2563: SECTOR PRIVADO | F2563: SI | G2563: NO | H2563: NO | I2563: 40 | J2563: =IF(ABS((C2563-AVERAGE($C:$C))/_xlfn.STDEV.S(moras[SALARIO]))>1.96,"Atípico","No") -> No | K2563: =IF(ABS((moras[[#This Row],[EDAD]]-AVERAGE($I:$I))/_xlfn.STDEV.S($I:$I))>1.96,"Atípico","No") -> No
A2564: 2387 | B2564: MUJER | C2564: 297046 | D2564: TRABAJADOR INDEPENDIENTE | E2564: SECTOR PRIVADO | F2564: SI | G2564: NO | H2564: SI | I2564: 40 | J2564: =IF(ABS((C2564-AVERAGE($C:$C))/_xlfn.STDEV.S(moras[SALARIO]))>1.96,"Atípico","No") -> No | K2564: =IF(ABS((moras[[#This Row],[EDAD]]-AVERAGE($I:$I))/_xlfn.STDEV.S($I:$I))>1.96,"Atípico","No") -> No
A2565: 2580 | B2565: HOMBRE | C2565: 297046 | D2565: ASEGURADO VOLUNTARIO | E2565: SECTOR PRIVADO | F2565: SI | G2565: NO | H2565: NO | I2565: 40 | J2565: =IF(ABS((C2565-AVERAGE($C:$C))/_xlfn.STDEV.S(moras[SALARIO]))>1.96,"Atípico","No") -> No | K2565: =IF(ABS((moras[[#This Row],[EDAD]]-AVERAGE($I:$I))/_xlfn.STDEV.S($I:$I))>1.96,"Atípico","No") -> No
A2566: 3118 | B2566: MUJER | C2566: 297046 | D2566: TRABAJADOR INDEPENDIENTE | E2566: SECTOR PRIVADO | F2566: SI | G2566: NO | H2566: SI | I2566: 40 | J2566: =IF(ABS((C2566-AVERAGE($C:$C))/_xlfn.STDEV.S(moras[SALARIO]))>1.96,"Atípico","No") -> No | K2566: =IF(ABS((moras[[#This Row],[EDAD]]-AVERAGE($I:$I))/_xlfn.STDEV.S($I:$I))>1.96,"Atípico","No") -> No
...

Sheet mora_imputada
A1: IDENTIFICACION | B1: SEXO | C1: SALARIO | D1: TIPO_ASEGURAMIENTO | E1: SECTOR | F1: INDICADOR_ACTIVO | G1: INDICADOR.EXTRANJERO | H1: INDICADOR_MOROSO | I1: EDAD | J1: SALARIO_ATÍPICO | K1: EDAD_ATÍPICO | L1: RANGOS_EDAD | M1: RANGOS_SALARIO
A2: 3411 | B2: HOMBRE | C2: 16858742 | D2: TRABAJADOR INDEPENDIENTE | E2: SECTOR PRIVADO | F2: SI | G2: NO | H2: NO | I2: 75 | J2: =IF(ABS((C2-AVERAGE($C:$C))/_xlfn.STDEV.S(moras2[SALARIO]))>1.96,"Atípico","No") -> Atípico | K2: =IF(ABS((moras2[[#This Row],[EDAD]]-AVERAGE($I:$I))/_xlfn.STDEV.S($I:$I))>1.96,"Atípico","No") -> Atípico | L2: =IF(I2<=35,"26-35",IF(I2<=45,"36-45",IF(I2<=55,"46-55","56+"))) -> 56+ | M2: =IF(C2<=500000,"0-500.000", IF(C2<=1000000,"500.001-1.000.000", IF(C2<=5000000,"1.000.001-5.000.000", "5.000.001-16.858.742"))) -> 5.000.001-16.858.742
A3: 3478 | B3: HOMBRE | C3: 14173194 | D3: PENSIONADOS EN SU PROPIO SISTEMA | E3: SECTOR PUBLICO | F3: SI | G3: NO | H3: NO | I3: 73 | J3: =IF(ABS((C3-AVERAGE($C:$C))/_xlfn.STDEV.S(moras2[SALARIO]))>1.96,"Atípico","No") -> Atípico | K3: =IF(ABS((moras2[[#This Row],[EDAD]]-AVERAGE($I:$I))/_xlfn.STDEV.S($I:$I))>1.96,"Atípico","No") -> Atípico | L3: =IF(I3<=35,"26-35",IF(I3<=45,"36-45",IF(I3<=55,"46-55","56+"))) -> 56+ | M3: =IF(C3<=500000,"0-500.000", IF(C3<=1000000,"500.001-1.000.000", IF(C3<=5000000,"1.000.001-5.000.000", "5.000.001-16.858.742"))) -> 5.000.001-16.858.742
A4: 1637 | B4: HOMBRE | C4: 12160184 | D4: ASALARIADO | E4: SECTOR PRIVADO | F4: SI | G4: NO | H4: NO | I4: 52 | J4: =IF(ABS((C4-AVERAGE($C:$C))/_xlfn.STDEV.S(moras2[SALARIO]))>1.96,"Atípico","No") -> Atípico | K4: =IF(ABS((moras2[[#This Row],[EDAD]]-AVERAGE($I:$I))/_xlfn.STDEV.S($I:$I))>1.96,"Atípico","No") -> No | L4: =IF(I4<=35,"26-35",IF(I4<=45,"36-45",IF(I4<=55,"46-55","56+"))) -> 46-55 | M4: =IF(C4<=500000,"0-500.000", IF(C4<=1000000,"500.001-1.000.000", IF(C4<=5000000,"1.000.001-5.000.000", "5.000.001-16.858.742"))) -> 5.000.001-16.858.742
A5: 1416 | B5: MUJER | C5: 11580186 | D5: ASALARIADO | E5: SECTOR PRIVADO | F5: SI | G5: NO | H5: NO | I5: 46 | J5: =IF(ABS((C5-AVERAGE($C:$C))/_xlfn.STDEV.S(moras2[SALARIO]))>1.96,"Atípico","No") -> Atípico | K5: =IF(ABS((moras2[[#This Row],[EDAD]]-AVERAGE($I:$I))/_xlfn.STDEV.S($I:$I))>1.96,"Atípico","No") -> No | L5: =IF(I5<=35,"26-35",IF(I5<=45,"36-45",IF(I5<=55,"46-55","56+"))) -> 46-55 | M5: =IF(C5<=500000,"0-500.000", IF(C5<=1000000,"500.001-1.000.000", IF(C5<=5000000,"1.000.001-5.000.000", "5.000.001-16.858.742"))) -> 5.000.001-16.858.742
A6: 3447 | B6: HOMBRE | C6: 11292324 | D6: ASALARIADO | E6: SECTOR PRIVADO | F6: SI | G6: SI | H6: NO | I6: 55 | J6: =IF(ABS((C6-AVERAGE($C:$C))/_xlfn.STDEV.S(moras2[SALARIO]))>1.96,"Atípico","No") -> Atípico | K6: =IF(ABS((moras2[[#This Row],[EDAD]]-AVERAGE($I:$I))/_xlfn.STDEV.S($I:$I))>1.96,"Atípico","No") -> No | L6: =IF(I6<=35,"26-35",IF(I6<=45,"36-45",IF(I6<=55,"46-55","56+"))) -> 46-55 | M6: =IF(C6<=500000,"0-500.000", IF(C6<=1000000,"500.001-1.000.000", IF(C6<=5000000,"1.000.001-5.000.000", "5.000.001-16.858.742"))) -> 5.000.001-16.858.742
A7: 3592 | B7: HOMBRE | C7: 9720000 | D7: ASALARIADO | E7: SECTOR PRIVADO | F7: SI | G7: SI | H7: NO | I7: 38 | J7: =IF(ABS((C7-AVERAGE($C:$C))/_xlfn.STDEV.S(moras2[SALARIO]))>1.96,"Atípico","No") -> Atípico | K7: =IF(ABS((moras2[[#This Row],[EDAD]]-AVERAGE($I:$I))/_xlfn.STDEV.S($I:$I))>1.96,"Atípico","No") -> No | L7: =IF(I7<=35,"26-35",IF(I7<=45,"36-45",IF(I7<=55,"46-55","56+"))) -> 36-45 | M7: =IF(C7<=500000,"0-500.000", IF(C7<=1000000,"500.001-1.000.000", IF(C7<=5000000,"1.000.001-5.000.000", "5.000.001-16.858.742"))) -> 5.000.001-16.858.742
A8: 4334 | B8: MUJER | C8: 9437618.5 | D8: ASALARIADO | E8: SECTOR PRIVADO | F8: SI | G8: NO | H8: NO | I8: 37 | J8: =IF(ABS((C8-AVERAGE($C:$C))/_xlfn.STDEV.S(moras2[SALARIO]))>1.96,"Atípico","No") -> Atípico | K8: =IF(ABS((moras2[[#This Row],[EDAD]]-AVERAGE($I:$I))/_xlfn.STDEV.S($I:$I))>1.96,"Atípico","No") -> No | L8: =IF(I8<=35,"26-35",IF(I8<=45,"36-45",IF(I8<=55,"46-55","56+"))) -> 36-45 | M8: =IF(C8<=500000,"0-500.000", IF(C8<=1000000,"500.001-1.000.000", IF(C8<=5000000,"1.000.001-5.000.000", "5.000.001-16.858.742"))) -> 5.000.001-16.858.742
A9: 4694 | B9: HOMBRE | C9: 8962309 | D9: PENSIONADOS EN SU PROPIO SISTEMA | E9: SECTOR PUBLICO | F9: SI | G9: NO | H9: NO | I9: 68 | J9: =IF(ABS((C9-AVERAGE($C:$C))/_xlfn.STDEV.S(moras2[SALARIO]))>1.96,"Atípico","No") -> Atípico | K9: =IF(ABS((moras2[[#This Row],[EDAD]]-AVERAGE($I:$I))/_xlfn.STDEV.S($I:$I))>1.96,"Atípico","No") -> No | L9: =IF(I9<=35,"26-35",IF(I9<=45,"36-45",IF(I9<=55,"46-55","56+"))) -> 56+ | M9: =IF(C9<=500000,"0-500.000", IF(C9<=1000000,"500.001-1.000.000", IF(C9<=5000000,"1.000.001-5.000.000", "5.000.001-16.858.742"))) -> 5.000.001-16.858.742
A10: 4219 | B10: HOMBRE | C10: 8850000 | D10: ASALARIADO | E10: SECTOR PRIVADO | F10: SI | G10: NO | H10: NO | I10: 41 | J10: =IF(ABS((C10-AVERAGE($C:$C))/_xlfn.STDEV.S(moras2[SALARIO]))>1.96,"Atípico","No") -> Atípico | K10: =IF(ABS((moras2[[#This Row],[EDAD]]-AVERAGE($I:$I))/_xlfn.STDEV.S($I:$I))>1.96,"Atípico","No") -> No | L10: =IF(I10<=35,"26-35",IF(I10<=45,"36-45",IF(I10<=55,"46-55","56+"))) -> 36-45 | M10: =IF(C10<=500000,"0-500.000", IF(C10<=1000000,"500.001-1.000.000", IF(C10<=5000000,"1.000.001-5.000.000", "5.000.001-16.858.742"))) -> 5.000.001-16.858.742
A11: 1719 | B11: MUJER | C11: 8457783.6 | D11: ASALARIADO | E11: SECTOR PRIVADO | F11: SI | G11: SI | H11: NO | I11: 55 | J11: =IF(ABS((C11-AVERAGE($C:$C))/_xlfn.STDEV.S(moras2[SALARIO]))>1.96,"Atípico","No") -> Atípico | K11: =IF(ABS((moras2[[#This Row],[EDAD]]-AVERAGE($I:$I))/_xlfn.STDEV.S($I:$I))>1.96,"Atípico","No") -> No | L11: =IF(I11<=35,"26-35",IF(I11<=45,"36-45",IF(I11<=55,"46-55","56+"))) -> 46-55 | M11: =IF(C11<=500000,"0-500.000", IF(C11<=1000000,"500.001-1.000.000", IF(C11<=5000000,"1.000.001-5.000.000", "5.000.001-16.858.742"))) -> 5.000.001-16.858.742
A12: 711 | B12: HOMBRE | C12: 8081401.8 | D12: ASALARIADO | E12: SECTOR PRIVADO | F12: SI | G12: NO | H12: NO | I12: 34 | J12: =IF(ABS((C12-AVERAGE($C:$C))/_xlfn.STDEV.S(moras2[SALARIO]))>1.96,"Atípico","No") -> Atípico | K12: =IF(ABS((moras2[[#This Row],[EDAD]]-AVERAGE($I:$I))/_xlfn.STDEV.S($I:$I))>1.96,"Atípico","No") -> No | L12: =IF(I12<=35,"26-35",IF(I12<=45,"36-45",IF(I12<=55,"46-55","56+"))) -> 26-35 | M12: =IF(C12<=500000,"0-500.000", IF(C12<=1000000,"500.001-1.000.000", IF(C12<=5000000,"1.000.001-5.000.000", "5.000.001-16.858.742"))) -> 5.000.001-16.858.742
A13: 4025 | B13: HOMBRE | C13: 7214352.2 | D13: ASALARIADO | E13: SECTOR PUBLICO | F13: SI | G13: NO | H13: NO | I13: 55 | J13: =IF(ABS((C13-AVERAGE($C:$C))/_xlfn.STDEV.S(moras2[SALARIO]))>1.96,"Atípico","No") -> Atípico | K13: =IF(ABS((moras2[[#This Row],[EDAD]]-AVERAGE($I:$I))/_xlfn.STDEV.S($I:$I))>1.96,"Atípico","No") -> No | L13: =IF(I13<=35,"26-35",IF(I13<=45,"36-45",IF(I13<=55,"46-55","56+"))) -> 46-55 | M13: =IF(C13<=500000,"0-500.000", IF(C13<=1000000,"500.001-1.000.000", IF(C13<=5000000,"1.000.001-5.000.000", "5.000.001-16.858.742"))) -> 5.000.001-16.858.742
... A5001: 2975 | B5001: MUJER | C5001: 10 | D5001: ASALARIADO | E5001: SECTOR PUBLICO | F5001: SI | G5001: NO | H5001: NO | I5001: 51 | J5001: =IF(ABS((C5001-AVERAGE($C:$C))/_xlfn.STDEV.S(moras2[SALARIO]))>1.96,"Atípico","No") -> No | K5001: =IF(ABS((moras2[[#This Row],[EDAD]]-AVERAGE($I:$I))/_xlfn.STDEV.S($I:$I))>1.96,"Atípico","No") -> No | L5001: =IF(I5001<=35,"26-35",IF(I5001<=45,"36-45",IF(I5001<=55,"46-55","56+"))) -> 46-55 | M5001: =IF(C5001<=500000,"0-500.000", IF(C5001<=1000000,"500.001-1.000.000", IF(C5001<=5000000,"1.000.001-5.000.000", "5.000.001-16.858.742"))) -> 0-500.000

Sheet Resolución de ejercicios
B26: Resumen de variables numéricas
B28: Variable | C28: Mínimo | D28: Q1 | E28: Mediana | F28: Q3 | G28: Máximo | H28: Promedio
B29: =moras[[#Headers],[SALARIO]] -> SALARIO | C29: =MIN(moras[SALARIO]) -> 10 | D29: =_xlfn.QUARTILE.INC(moras[SALARIO],1) -> 297429 | E29: =MEDIAN(moras[SALARIO]) -> 408495 | F29: =_xlfn.QUARTILE.INC(moras[SALARIO],3) -> 700000 | G29: =MAX(moras[SALARIO]) -> 16858742 | H29: =AVERAGE(moras[SALARIO]) -> 657534.29
B30: =moras[[#Headers],[EDAD]] -> EDAD | C30: =MIN(moras[EDAD]) -> 14 | D30: =_xlfn.QUARTILE.INC(moras[EDAD],1) -> 31 | E30: =MEDIAN(moras[EDAD]) -> 40 | F30: =_xlfn.QUARTILE.INC(moras[EDAD],3) -> 52 | G30: =MAX(moras[EDAD]) -> 99 | H30: =AVERAGE(moras[EDAD]) -> 41.906344
B34: Porcentajes de valores faltantes
B36: Variable | C36: Porcentaje
B37: =moras[[#Headers],[IDENTIFICACION]] -> IDENTIFICACION | C37: =COUNTBLANK(moras[IDENTIFICACION]) / ROWS(moras[IDENTIFICACION]) -> 0
B38: =moras[[#Headers],[SEXO]] -> SEXO | C38: =COUNTBLANK(moras[SEXO]) / ROWS(moras[SEXO]) -> 0
B39: =moras[[#Headers],[SALARIO]] -> SALARIO | C39: =COUNTBLANK(moras[SALARIO]) / ROWS(moras[SALARIO]) -> 0.0006
B40: =moras[[#Headers],[TIPO_ASEGURAMIENTO]] -> TIPO_ASEGURAMIENTO | C40: =COUNTBLANK(moras[TIPO_ASEGURAMIENTO]) / ROWS(moras[TIPO_ASEGURAMIENTO]) -> 0.0004
B41: =moras[[#Headers],[SECTOR]] -> SECTOR | C41: =COUNTBLANK(moras[SECTOR]) / ROWS(moras[SECTOR]) -> 0
B42: =moras[[#Headers],[INDICADOR_ACTIVO]] -> INDICADOR_ACTIVO | C42: =COUNTBLANK(moras[INDICADOR_ACTIVO]) / ROWS(moras[INDICADOR_ACTIVO]) -> 0
B43: =moras[[#Headers],[INDICADOR.EXTRANJERO]] -> INDICADOR.EXTRANJERO | C43: =COUNTBLANK(moras[INDICADOR.EXTRANJERO]) / ROWS(moras[INDICADOR.EXTRANJERO]) -> 0
B44: =moras[[#Headers],[INDICADOR_MOROSO]] -> INDICADOR_MOROSO | C44: =COUNTBLANK(moras[INDICADOR_MOROSO]) / ROWS(moras[INDICADOR_MOROSO]) -> 0
B45: =moras[[#Headers],[EDAD]] -> EDAD | C45: =COUNTBLANK(moras[EDAD]) / ROWS(moras[EDAD]) -> 0.0006
B46: =moras[[#Headers],[SALARIO_ATÍPICO]] -> SALARIO_ATÍPICO | C46: =COUNTBLANK(moras[SALARIO_ATÍPICO]) / ROWS(moras[SALARIO_ATÍPICO]) -> 0
B47: =moras[[#Headers],[EDAD_ATÍPICO]] -> EDAD_ATÍPICO | C47: =COUNTBLANK(moras[EDAD_ATÍPICO]) / ROWS(moras[EDAD_ATÍPICO]) -> 0
H51: Cantidad de personas
H52: MUJERES | I52: =COUNTIF(moras[SEXO],"MUJER") -> 1988
H53: HOMBRES | I53: =COUNTIF(moras[SEXO],"HOMBRE") -> 3012
H68: Cantidad de personas por título de aseguramiento
H69: {=_xlfn.UNIQUE(moras2[TIPO_ASEGURAMIENTO])} -> TRABAJADOR INDEPENDIENTE | I69: =COUNTIF(moras2[TIPO_ASEGURAMIENTO], 'Resolución de ejercicios'!H69) -> 700
H70: PENSIONADOS EN SU PROPIO SISTEMA | I70: =COUNTIF(moras2[TIPO_ASEGURAMIENTO], 'Resolución de ejercicios'!H70) -> 212
H71: ASALARIADO | I71: =COUNTIF(moras2[TIPO_ASEGURAMIENTO], 'Resolución de ejercicios'!H71) -> 3464
H72: CONVENIOS ESPECIALES DE ASEGURADOS VOLUNTARIOS | I72: =COUNTIF(moras2[TIPO_ASEGURAMIENTO], 'Resolución de ejercicios'!H72) -> 31
H73: CONVENIOS ESPECIALES DE TRABAJADORES INDEPENDIENTES | I73: =COUNTIF(moras2[TIPO_ASEGURAMIENTO], 'Resolución de ejercicios'!H73) -> 157
H74: ASEGURADO VOLUNTARIO | I74: =COUNTIF(moras2[TIPO_ASEGURAMIENTO], 'Resolución de ejercicios'!H74) -> 436
H85: Cantidad de personas por sector
H86: {=_xlfn.UNIQUE(moras2[SECTOR])} -> SECTOR PRIVADO | I86: =COUNTIF(moras2[SECTOR], H86) -> 3906
H87: SECTOR PUBLICO | I87: =COUNTIF(moras2[SECTOR], H87) -> 1094
H102: Cantidad de personas que tienen activo el seguro
H103: {=_xlfn.UNIQUE(moras2[INDICADOR_ACTIVO])} -> SI | I103: =COUNTIF(moras2[INDICADOR_ACTIVO], H103) -> 4966
H104: NO | I104: =COUNTIF(moras2[INDICADOR_ACTIVO], H104) -> 34
H119: Cantidad de personas extranjeras
H120: {=_xlfn.UNIQUE(moras2[INDICADOR.EXTRANJERO])} -> NO | I120: =COUNTIF(moras2[INDICADOR.EXTRANJERO], H120) -> 4397
H121: SI | I121: =COUNTIF(moras2[INDICADOR.EXTRANJERO], H121) -> 603
H136: Cantidad de morosos
H137: {=_xlfn.UNIQUE(moras2[INDICADOR_MOROSO])} -> NO | I137: =COUNTIF(moras2[INDICADOR_MOROSO], H137) -> 4130
H138: SI | I138: =COUNTIF(moras2[INDICADOR_MOROSO], H138) -> 870
H155: Sexo | I155: Porcentaje de morosos | J155: Cantidad por sexo | K155: Cantidad de morosos
...
